
## 从零手撕Promise，掌握Promise的实现原理。(2)
## 上篇文章介绍到`Promise`的基本结构，如下
  文章地址
  ```js
    const PENDING = 'pending'
    const FULFILLED = 'fulfilled'
    const REJECTED = 'rejected'

    class Promise{
      constructor(executor){

        this.state = PENDING
        this.value = undefined
        this.reason = undefined

        const resolve = (value) => {

        }

        const reject = (reason) => {

        }

          executor(resolve,reject)

      }

      then(onFulfilled, onRejected){


      }
    }
  ```
## 实现基础版本的`Promise`
## resolve与reject实现
- 1. 如果调用`resolve`会让状态变成成功态，调用`reject`会让状态变成失败态,并且状态改变后再次调用`resolve`与`reject`将不再起作用.
  -  `resolve`与`reject`函数实现
     ```js
        const resolve = (value) => {
          if (this.state === PENDING) {
              this.value = value
              this.state = FULFILLED
          }
        }

        const reject = (reason) => {
          if (this.state === PENDING) {
            this.reason = reason
            this.state = REJECTED
          }
        }
     ```
## then方法实现
- 1. `new Promise`会产生一个`promise`实例, `promise`实例拥有一个`then`方法，第一个参数是成功的回调(`onFulfilled`)，第二个参数是失败的回调(`onRejected`).当我们调用实例上的`then`方法时，如果`promise`实例是成功的状态，则会调用`onFulfilled`,参数为`promise`实例成功的值(`value`)；如果`promise`实例是失败的状态，则会调用`onRejected`,参数为`promise`实例失败的原因(`reason`)。
  - `then`方法初步实现
    ```js
       then(onFulfilled, onRejected){
         if (this.state === FULFILLED) {
            onFulfilled(this.value)
         }

        if (this.state === REJECTED) {
          onRejected(this.reason)
        }
       } 
    ```
- 2. 但是这样的话问题又来了，当我像如下这样`new`一个`Promise`呢。很明显当我调用实例`p`上的`then`方法的时候，实例`p`的状态还不确定。
  ```js
      let p = new Promise((resolve, reject) => {
          setTimeout(() => {
              resolve('成功')
          }, 1000);
      })
      p.then(value => {
          console.log(value, '成功')
      }, reason => {
          console.log(reason, '失败')
      })
  ```
- 3. 对于上面这个问题我们需要改造我们的`then`方法，当我们调用`then`方法的时候，如果此时`promise`实例的状态还是`pending`状态，我们需要把`onFulfilled`函数与`onRejected`函数存起来，当`promise`实例的状态改变时再去调用，因此我们还需要改造`resolve`与`reject`函数。
  - 此外`new Promise`的时候，需要传入一个执行函数executor ， executor默认会立即执行，假如执行过程中出错，那么我们需要调用`reject`，将错误原因作为参数传进去，`promise`实例的状态将会改为失败。
  - 改造后的`Promise`，如下
  ```js
      const PENDING = 'pending'
      const FULFILLED = 'fulfilled'
      const REJECTED = 'rejected'

      class Promise{
        constructor(executor){

          this.state = PENDING
          this.value = undefined
          this.reason = undefined
          //存放onFulfilled
          this.onResolvedCallbacks = []
          //存放onRejected
          this.onRejectedCallbacks = []
          const resolve = (value) => {
            if (this.state === PENDING) {
              this.value = value
              this.state = FULFILLED
              //promise实例状态改变后调用暂存的onFulfilled
              this.onResolvedCallbacks.forEach(fn => fn())
            }
          }

          const reject = (reason) => {
            if (this.state === PENDING) {
              this.reason = reason
              this.state = REJECTED
              //promise实例状态改变后调用的onRejected
              this.onRejectedCallbacks.forEach(fn => fn())
            }
          }
          try {
            executor(resolve,reject)
          } catch (error) {
            reject(error)
          }
        }
        then(onFulfilled, onRejected){
          if (this.state === FULFILLED) {
            onFulfilled(this.value)
          }

          if (this.state === REJECTED) {
            onRejected(this.reason)
          }

          if (this.state === PENDING) {
            //如果此时promise实例的状态还未确定，我们需要将onFulfilled与onRejected存起来，等到promise实例状态改变后再去调用
            this.onResolvedCallbacks.push(() => {
              onFulfilled(this.value)
            })
            this.onResolvedCallbacks.push(() => {
              onRejected(this.reason)
            })
          }

        }
      }
  ```
  - 到此时检验一下我们的promise
  ```js
    let p = new Promise((resolve, reject) => {
        setTimeout(() => {
            resolve('成功')
        }, 1000);
    })
    p.then(value => {
        console.log(value, '成功')
    }, reason => {
        console.log(reason, '失败')
    })
  ```
  
